During handling of the above exception, another exception occurred:

Traceback (most recent call last):
  File "/home/asgan/projects/SteamAppsDB/venv/lib/python3.10/site-packages/requests/adapters.py", line 440, in send
    resp = conn.urlopen(
  File "/home/asgan/projects/SteamAppsDB/venv/lib/python3.10/site-packages/urllib3/connectionpool.py", line 785, in urlopen
    retries = retries.increment(
  File "/home/asgan/projects/SteamAppsDB/venv/lib/python3.10/site-packages/urllib3/util/retry.py", line 592, in increment
    raise MaxRetryError(_pool, url, error or ResponseError(cause))
urllib3.exceptions.MaxRetryError: HTTPSConnectionPool(host='steamspy.com', port=443): Max retries exceeded with url: /api.php?request=appdetails&appid=203700 (Caused by NewConnectionError('<urllib3.connection.HTTPSConnection object at 0x7f8c4296ae60>: Failed to establish a new connection: [Errno 101] Network is unreachable'))

During handling of the above exception, another exception occurred:

Traceback (most recent call last):
  File "/home/asgan/projects/SteamAppsDB/db/update.py", line 518, in <module>
    raise e
  File "/home/asgan/projects/SteamAppsDB/db/update.py", line 483, in <module>
    main()
  File "/home/asgan/projects/SteamAppsDB/db/update.py", line 151, in main
    steamspy_data = fetch(steamspy_api)
  File "/home/asgan/projects/SteamAppsDB/db/update.py", line 234, in fetch
    response = request_from(api)
  File "/home/asgan/projects/SteamAppsDB/db/update.py", line 297, in request_from
    response = requests.get(api, timeout=timeout)
  File "/home/asgan/projects/SteamAppsDB/venv/lib/python3.10/site-packages/requests/api.py", line 75, in get
    return request('get', url, params=params, **kwargs)
  File "/home/asgan/projects/SteamAppsDB/venv/lib/python3.10/site-packages/requests/api.py", line 61, in request
    return session.request(method=method, url=url, **kwargs)
  File "/home/asgan/projects/SteamAppsDB/venv/lib/python3.10/site-packages/requests/sessions.py", line 529, in request
    resp = self.send(prep, **send_kwargs)
  File "/home/asgan/projects/SteamAppsDB/venv/lib/python3.10/site-packages/requests/sessions.py", line 645, in send
    r = adapter.send(request, **kwargs)
  File "/home/asgan/projects/SteamAppsDB/venv/lib/python3.10/site-packages/requests/adapters.py", line 519, in send
    raise ConnectionError(e, request=request)
requests.exceptions.ConnectionError: HTTPSConnectionPool(host='steamspy.com', port=443): Max retries exceeded with url: /api.php?request=appdetails&appid=203700 (Caused by NewConnectionError('<urllib3.connection.HTTPSConnection object at 0x7f8c4296ae60>: Failed to establish a new connection: [Errno 101] Network is unreachable'))
